--- Logging error ---
Traceback (most recent call last):
  File "/home/steff007/.local/lib/python3.10/site-packages/pip/_internal/utils/logging.py", line 177, in emit
    self.console.print(renderable, overflow="ignore", crop=False, style=style)
  File "/home/steff007/.local/lib/python3.10/site-packages/pip/_vendor/rich/console.py", line 1673, in print
    extend(render(renderable, render_options))
  File "/home/steff007/.local/lib/python3.10/site-packages/pip/_vendor/rich/console.py", line 1305, in render
    for render_output in iter_render:
  File "/home/steff007/.local/lib/python3.10/site-packages/pip/_internal/utils/logging.py", line 134, in __rich_console__
    for line in lines:
  File "/home/steff007/.local/lib/python3.10/site-packages/pip/_vendor/rich/segment.py", line 249, in split_lines
    for segment in segments:
  File "/home/steff007/.local/lib/python3.10/site-packages/pip/_vendor/rich/console.py", line 1283, in render
    renderable = rich_cast(renderable)
  File "/home/steff007/.local/lib/python3.10/site-packages/pip/_vendor/rich/protocol.py", line 36, in rich_cast
    renderable = cast_method()
  File "/home/steff007/.local/lib/python3.10/site-packages/pip/_internal/self_outdated_check.py", line 130, in __rich__
    pip_cmd = get_best_invocation_for_this_pip()
  File "/home/steff007/.local/lib/python3.10/site-packages/pip/_internal/utils/entrypoints.py", line 58, in get_best_invocation_for_this_pip
    if found_executable and os.path.samefile(
  File "/usr/lib/python3.10/genericpath.py", line 101, in samefile
    s2 = os.stat(f2)
FileNotFoundError: [Errno 2] No such file or directory: '/usr/bin/pip'
Call stack:
  File "/usr/lib/python3.10/runpy.py", line 196, in _run_module_as_main
    return _run_code(code, main_globals, None,
  File "/usr/lib/python3.10/runpy.py", line 86, in _run_code
    exec(code, run_globals)
  File "/home/steff007/.local/lib/python3.10/site-packages/pip/__main__.py", line 31, in <module>
    sys.exit(_main())
  File "/home/steff007/.local/lib/python3.10/site-packages/pip/_internal/cli/main.py", line 70, in main
    return command.main(cmd_args)
  File "/home/steff007/.local/lib/python3.10/site-packages/pip/_internal/cli/base_command.py", line 101, in main
    return self._main(args)
  File "/home/steff007/.local/lib/python3.10/site-packages/pip/_internal/cli/base_command.py", line 223, in _main
    self.handle_pip_version_check(options)
  File "/home/steff007/.local/lib/python3.10/site-packages/pip/_internal/cli/req_command.py", line 190, in handle_pip_version_check
    pip_self_version_check(session, options)
  File "/home/steff007/.local/lib/python3.10/site-packages/pip/_internal/self_outdated_check.py", line 236, in pip_self_version_check
    logger.warning("[present-rich] %s", upgrade_prompt)
  File "/usr/lib/python3.10/logging/__init__.py", line 1489, in warning
    self._log(WARNING, msg, args, **kwargs)
  File "/usr/lib/python3.10/logging/__init__.py", line 1624, in _log
    self.handle(record)
  File "/usr/lib/python3.10/logging/__init__.py", line 1634, in handle
    self.callHandlers(record)
  File "/usr/lib/python3.10/logging/__init__.py", line 1696, in callHandlers
    hdlr.handle(record)
  File "/usr/lib/python3.10/logging/__init__.py", line 968, in handle
    self.emit(record)
  File "/home/steff007/.local/lib/python3.10/site-packages/pip/_internal/utils/logging.py", line 179, in emit
    self.handleError(record)
Message: '[present-rich] %s'
Arguments: (UpgradePrompt(old='22.2.1', new='22.2.2'),)
